[W 210224 09:30:26 web:2239] 404 GET / (172.25.0.1) 3.64ms
[W 210224 09:30:26 web:2239] 404 GET /favicon.ico (172.25.0.1) 1.24ms
[W 210224 09:30:28 web:2239] 404 GET /public (172.25.0.1) 0.81ms
[W 210224 09:30:28 web:2239] 404 GET /favicon.ico (172.25.0.1) 3.22ms
[E 210224 09:30:35 web:1789] Uncaught exception GET /patient/insurance/detail (172.25.0.1)
    HTTPServerRequest(protocol='http', host='localhost:8081', method='GET', uri='/patient/insurance/detail', version='HTTP/1.1', remote_ip='172.25.0.1')
    Traceback (most recent call last):
      File "/usr/local/lib/python3.8/site-packages/tornado/web.py", line 1702, in _execute
        result = method(*self.path_args, **self.path_kwargs)
    TypeError: get() missing 1 required positional argument: '_id'
[E 210224 09:30:35 web:2239] 500 GET /patient/insurance/detail (172.25.0.1) 4.54ms
[W 210224 09:30:36 web:2239] 404 GET /favicon.ico (172.25.0.1) 2.24ms
[I 210224 09:31:38 autoreload:201] /usr/src/app/handlers/endpoints.py modified; restarting server
[E 210224 09:31:41 web:1789] Uncaught exception GET /patient/insurance/detail (172.25.0.1)
    HTTPServerRequest(protocol='http', host='localhost:8081', method='GET', uri='/patient/insurance/detail', version='HTTP/1.1', remote_ip='172.25.0.1')
    Traceback (most recent call last):
      File "/usr/local/lib/python3.8/site-packages/tornado/web.py", line 1702, in _execute
        result = method(*self.path_args, **self.path_kwargs)
    TypeError: get() missing 1 required positional argument: '_id'
[E 210224 09:31:41 web:2239] 500 GET /patient/insurance/detail (172.25.0.1) 6.07ms
[E 210224 09:31:42 web:1789] Uncaught exception GET /patient/insurance/detail (172.25.0.1)
    HTTPServerRequest(protocol='http', host='localhost:8081', method='GET', uri='/patient/insurance/detail', version='HTTP/1.1', remote_ip='172.25.0.1')
    Traceback (most recent call last):
      File "/usr/local/lib/python3.8/site-packages/tornado/web.py", line 1702, in _execute
        result = method(*self.path_args, **self.path_kwargs)
    TypeError: get() missing 1 required positional argument: '_id'
[E 210224 09:31:42 web:2239] 500 GET /patient/insurance/detail (172.25.0.1) 19.40ms
[I 210224 09:32:40 autoreload:201] /usr/src/app/handlers/endpoints.py modified; restarting server
[I 210224 09:32:44 autoreload:201] /usr/src/app/handlers/endpoints.py modified; restarting server
[E 210224 09:32:48 web:1789] Uncaught exception GET /patient/insurance/detail (172.25.0.1)
    HTTPServerRequest(protocol='http', host='localhost:8081', method='GET', uri='/patient/insurance/detail', version='HTTP/1.1', remote_ip='172.25.0.1')
    Traceback (most recent call last):
      File "/usr/local/lib/python3.8/site-packages/tornado/web.py", line 1704, in _execute
        result = await result
      File "/usr/src/app/handlers/endpoints.py", line 30, in get
        doc = await self.db.master.find_one({"pid": 7728}, {"policy"})
      File "/usr/local/lib/python3.8/site-packages/motor/core.py", line 761, in __call__
        raise TypeError(
    TypeError: MotorCollection object is not callable. If you meant to call the 'find_one' method on a MotorCollection object it is failing because no such method exists.
[E 210224 09:32:49 web:2239] 500 GET /patient/insurance/detail (172.25.0.1) 11.26ms
[I 210224 09:36:05 autoreload:201] /usr/src/app/handlers/endpoints.py modified; restarting server
[E 210224 09:36:11 web:1789] Uncaught exception GET /patient/insurance/detail (172.25.0.1)
    HTTPServerRequest(protocol='http', host='localhost:8081', method='GET', uri='/patient/insurance/detail', version='HTTP/1.1', remote_ip='172.25.0.1')
    Traceback (most recent call last):
      File "/usr/local/lib/python3.8/site-packages/tornado/web.py", line 1704, in _execute
        result = await result
      File "/usr/src/app/handlers/endpoints.py", line 30, in get
        doc = await self.db.master.find_one()
      File "/usr/local/lib/python3.8/site-packages/motor/core.py", line 761, in __call__
        raise TypeError(
    TypeError: MotorCollection object is not callable. If you meant to call the 'find_one' method on a MotorCollection object it is failing because no such method exists.
[E 210224 09:36:11 web:2239] 500 GET /patient/insurance/detail (172.25.0.1) 9.30ms
[E 210224 09:36:13 web:1789] Uncaught exception GET /patient/insurance/detail (172.25.0.1)
    HTTPServerRequest(protocol='http', host='localhost:8081', method='GET', uri='/patient/insurance/detail', version='HTTP/1.1', remote_ip='172.25.0.1')
    Traceback (most recent call last):
      File "/usr/local/lib/python3.8/site-packages/tornado/web.py", line 1704, in _execute
        result = await result
      File "/usr/src/app/handlers/endpoints.py", line 30, in get
        doc = await self.db.master.find_one()
      File "/usr/local/lib/python3.8/site-packages/motor/core.py", line 761, in __call__
        raise TypeError(
    TypeError: MotorCollection object is not callable. If you meant to call the 'find_one' method on a MotorCollection object it is failing because no such method exists.
[E 210224 09:36:13 web:2239] 500 GET /patient/insurance/detail (172.25.0.1) 6.28ms
[I 210224 09:38:30 autoreload:201] /usr/src/app/handlers/endpoints.py modified; restarting server
[E 210224 09:38:37 web:1789] Uncaught exception GET /patient/insurance/detail (172.25.0.1)
    HTTPServerRequest(protocol='http', host='localhost:8081', method='GET', uri='/patient/insurance/detail', version='HTTP/1.1', remote_ip='172.25.0.1')
    Traceback (most recent call last):
      File "/usr/local/lib/python3.8/site-packages/tornado/web.py", line 1704, in _execute
        result = await result
      File "/usr/src/app/handlers/endpoints.py", line 30, in get
        doc = await self.db.master.find_one()
      File "/usr/local/lib/python3.8/site-packages/motor/core.py", line 761, in __call__
        raise TypeError(
    TypeError: MotorCollection object is not callable. If you meant to call the 'find_one' method on a MotorCollection object it is failing because no such method exists.
[E 210224 09:38:37 web:2239] 500 GET /patient/insurance/detail (172.25.0.1) 14.51ms
[E 210224 09:38:38 web:1789] Uncaught exception GET /patient/insurance/detail (172.25.0.1)
    HTTPServerRequest(protocol='http', host='localhost:8081', method='GET', uri='/patient/insurance/detail', version='HTTP/1.1', remote_ip='172.25.0.1')
    Traceback (most recent call last):
      File "/usr/local/lib/python3.8/site-packages/tornado/web.py", line 1704, in _execute
        result = await result
      File "/usr/src/app/handlers/endpoints.py", line 30, in get
        doc = await self.db.master.find_one()
      File "/usr/local/lib/python3.8/site-packages/motor/core.py", line 761, in __call__
        raise TypeError(
    TypeError: MotorCollection object is not callable. If you meant to call the 'find_one' method on a MotorCollection object it is failing because no such method exists.
[E 210224 09:38:38 web:2239] 500 GET /patient/insurance/detail (172.25.0.1) 4.37ms
[E 210224 09:41:22 web:1789] Uncaught exception GET /patient/insurance/detail (172.25.0.1)
    HTTPServerRequest(protocol='http', host='localhost:8081', method='GET', uri='/patient/insurance/detail', version='HTTP/1.1', remote_ip='172.25.0.1')
    Traceback (most recent call last):
      File "/usr/local/lib/python3.8/site-packages/tornado/web.py", line 1704, in _execute
        result = await result
      File "/usr/src/app/handlers/endpoints.py", line 30, in get
        doc = await self.db.master.find_one()
      File "/usr/local/lib/python3.8/site-packages/motor/core.py", line 761, in __call__
        raise TypeError(
    TypeError: MotorCollection object is not callable. If you meant to call the 'find_one' method on a MotorCollection object it is failing because no such method exists.
[E 210224 09:41:22 web:2239] 500 GET /patient/insurance/detail (172.25.0.1) 7.40ms
[E 210224 09:41:28 web:1789] Uncaught exception GET /patient/insurance/detail (172.25.0.1)
    HTTPServerRequest(protocol='http', host='localhost:8081', method='GET', uri='/patient/insurance/detail', version='HTTP/1.1', remote_ip='172.25.0.1')
    Traceback (most recent call last):
      File "/usr/local/lib/python3.8/site-packages/tornado/web.py", line 1704, in _execute
        result = await result
      File "/usr/src/app/handlers/endpoints.py", line 30, in get
        doc = await self.db.master.find_one()
      File "/usr/local/lib/python3.8/site-packages/motor/core.py", line 761, in __call__
        raise TypeError(
    TypeError: MotorCollection object is not callable. If you meant to call the 'find_one' method on a MotorCollection object it is failing because no such method exists.
[E 210224 09:41:28 web:2239] 500 GET /patient/insurance/detail (172.25.0.1) 7.97ms
[E 210224 09:41:29 web:1789] Uncaught exception GET /patient/insurance/detail (172.25.0.1)
    HTTPServerRequest(protocol='http', host='localhost:8081', method='GET', uri='/patient/insurance/detail', version='HTTP/1.1', remote_ip='172.25.0.1')
    Traceback (most recent call last):
      File "/usr/local/lib/python3.8/site-packages/tornado/web.py", line 1704, in _execute
        result = await result
      File "/usr/src/app/handlers/endpoints.py", line 30, in get
        doc = await self.db.master.find_one()
      File "/usr/local/lib/python3.8/site-packages/motor/core.py", line 761, in __call__
        raise TypeError(
    TypeError: MotorCollection object is not callable. If you meant to call the 'find_one' method on a MotorCollection object it is failing because no such method exists.
[E 210224 09:41:29 web:2239] 500 GET /patient/insurance/detail (172.25.0.1) 9.40ms
[I 210224 09:42:32 autoreload:201] /usr/src/app/handlers/endpoints.py modified; restarting server
[E 210224 09:42:37 web:1789] Uncaught exception GET /patient/insurance/detail (172.25.0.1)
    HTTPServerRequest(protocol='http', host='localhost:8081', method='GET', uri='/patient/insurance/detail', version='HTTP/1.1', remote_ip='172.25.0.1')
    Traceback (most recent call last):
      File "/usr/local/lib/python3.8/site-packages/tornado/web.py", line 1704, in _execute
        result = await result
      File "/usr/src/app/handlers/endpoints.py", line 30, in get
        doc = await self.db.master.find_one()
      File "/usr/local/lib/python3.8/site-packages/motor/core.py", line 761, in __call__
        raise TypeError(
    TypeError: MotorCollection object is not callable. If you meant to call the 'find_one' method on a MotorCollection object it is failing because no such method exists.
[E 210224 09:42:37 web:2239] 500 GET /patient/insurance/detail (172.25.0.1) 9.18ms
[I 210224 09:42:45 autoreload:201] /usr/src/app/handlers/endpoints.py modified; restarting server
[E 210224 09:42:50 web:1789] Uncaught exception GET /patient/insurance/detail (172.25.0.1)
    HTTPServerRequest(protocol='http', host='localhost:8081', method='GET', uri='/patient/insurance/detail', version='HTTP/1.1', remote_ip='172.25.0.1')
    Traceback (most recent call last):
      File "/usr/local/lib/python3.8/site-packages/tornado/web.py", line 1704, in _execute
        result = await result
      File "/usr/src/app/handlers/endpoints.py", line 31, in get
        doc = await self.db.master.find_one()
      File "/usr/local/lib/python3.8/site-packages/motor/core.py", line 761, in __call__
        raise TypeError(
    TypeError: MotorCollection object is not callable. If you meant to call the 'find_one' method on a MotorCollection object it is failing because no such method exists.
[E 210224 09:42:50 web:2239] 500 GET /patient/insurance/detail (172.25.0.1) 18.95ms
[I 210224 09:43:21 autoreload:201] /usr/src/app/handlers/endpoints.py modified; restarting server
[E 210224 09:43:26 web:1789] Uncaught exception GET /patient/insurance/detail (172.25.0.1)
    HTTPServerRequest(protocol='http', host='localhost:8081', method='GET', uri='/patient/insurance/detail', version='HTTP/1.1', remote_ip='172.25.0.1')
    Traceback (most recent call last):
      File "/usr/local/lib/python3.8/site-packages/tornado/web.py", line 1704, in _execute
        result = await result
      File "/usr/src/app/handlers/endpoints.py", line 31, in get
        doc = await self.db.master.find_one()
      File "/usr/local/lib/python3.8/site-packages/motor/core.py", line 761, in __call__
        raise TypeError(
    TypeError: MotorCollection object is not callable. If you meant to call the 'find_one' method on a MotorCollection object it is failing because no such method exists.
[E 210224 09:43:26 web:2239] 500 GET /patient/insurance/detail (172.25.0.1) 11.66ms
[I 210224 09:44:54 autoreload:201] /usr/src/app/handlers/endpoints.py modified; restarting server
[E 210224 09:45:02 web:1789] Uncaught exception GET /patient/insurance/detail (172.25.0.1)
    HTTPServerRequest(protocol='http', host='localhost:8081', method='GET', uri='/patient/insurance/detail', version='HTTP/1.1', remote_ip='172.25.0.1')
    Traceback (most recent call last):
      File "/usr/local/lib/python3.8/site-packages/tornado/web.py", line 1704, in _execute
        result = await result
      File "/usr/src/app/handlers/endpoints.py", line 31, in get
        doc = await self.db.master.find_one()
      File "/usr/local/lib/python3.8/site-packages/motor/core.py", line 761, in __call__
        raise TypeError(
    TypeError: MotorCollection object is not callable. If you meant to call the 'find_one' method on a MotorCollection object it is failing because no such method exists.
[E 210224 09:45:02 web:2239] 500 GET /patient/insurance/detail (172.25.0.1) 10.76ms
[I 210224 09:46:45 autoreload:201] /usr/src/app/handlers/endpoints.py modified; restarting server
[E 210224 09:46:48 web:1789] Uncaught exception GET /patient/insurance/detail (172.25.0.1)
    HTTPServerRequest(protocol='http', host='localhost:8081', method='GET', uri='/patient/insurance/detail', version='HTTP/1.1', remote_ip='172.25.0.1')
    Traceback (most recent call last):
      File "/usr/local/lib/python3.8/site-packages/tornado/web.py", line 1704, in _execute
        result = await result
      File "/usr/src/app/handlers/endpoints.py", line 30, in get
        doc = await self.db.master.find_one()
      File "/usr/local/lib/python3.8/site-packages/motor/core.py", line 761, in __call__
        raise TypeError(
    TypeError: MotorCollection object is not callable. If you meant to call the 'find_one' method on a MotorCollection object it is failing because no such method exists.
[E 210224 09:46:48 web:2239] 500 GET /patient/insurance/detail (172.25.0.1) 11.92ms
[I 210224 09:49:14 autoreload:201] /usr/src/app/settings.py modified; restarting server
[E 210224 09:50:50 web:1789] Uncaught exception GET /patient/insurance/detail (172.25.0.1)
    HTTPServerRequest(protocol='http', host='localhost:8081', method='GET', uri='/patient/insurance/detail', version='HTTP/1.1', remote_ip='172.25.0.1')
    Traceback (most recent call last):
      File "/usr/local/lib/python3.8/site-packages/tornado/web.py", line 1704, in _execute
        result = await result
      File "/usr/src/app/handlers/endpoints.py", line 30, in get
        doc = await self.db.master.find_one()
      File "/usr/src/app/handlers/core.py", line 36, in db
        raise Exception("DB is not initialised!!")
    Exception: DB is not initialised!!
[E 210224 09:50:50 web:2239] 500 GET /patient/insurance/detail (172.25.0.1) 28.46ms
[I 210224 09:51:26 autoreload:201] /usr/src/app/settings.py modified; restarting server
[I 210224 09:51:36 autoreload:201] /usr/src/app/settings.py modified; restarting server
[E 210224 09:52:13 web:1789] Uncaught exception GET /patient/insurance/detail (172.25.0.1)
    HTTPServerRequest(protocol='http', host='localhost:8081', method='GET', uri='/patient/insurance/detail', version='HTTP/1.1', remote_ip='172.25.0.1')
    Traceback (most recent call last):
      File "/usr/local/lib/python3.8/site-packages/tornado/web.py", line 1704, in _execute
        result = await result
      File "/usr/src/app/handlers/endpoints.py", line 30, in get
        doc = await self.db.master.find_one()
      File "/usr/local/lib/python3.8/concurrent/futures/thread.py", line 57, in run
        result = self.fn(*self.args, **self.kwargs)
      File "/usr/local/lib/python3.8/site-packages/pymongo/collection.py", line 1319, in find_one
        for result in cursor.limit(-1):
      File "/usr/local/lib/python3.8/site-packages/pymongo/cursor.py", line 1207, in next
        if len(self.__data) or self._refresh():
      File "/usr/local/lib/python3.8/site-packages/pymongo/cursor.py", line 1100, in _refresh
        self.__session = self.__collection.database.client._ensure_session()
      File "/usr/local/lib/python3.8/site-packages/pymongo/mongo_client.py", line 1816, in _ensure_session
        return self.__start_session(True, causal_consistency=False)
      File "/usr/local/lib/python3.8/site-packages/pymongo/mongo_client.py", line 1766, in __start_session
        server_session = self._get_server_session()
      File "/usr/local/lib/python3.8/site-packages/pymongo/mongo_client.py", line 1802, in _get_server_session
        return self._topology.get_server_session()
      File "/usr/local/lib/python3.8/site-packages/pymongo/topology.py", line 485, in get_server_session
        self._select_servers_loop(
      File "/usr/local/lib/python3.8/site-packages/pymongo/topology.py", line 215, in _select_servers_loop
        raise ServerSelectionTimeoutError(
    pymongo.errors.ServerSelectionTimeoutError: localhost:27017: [Errno 111] Connection refused, Timeout: 30s, Topology Description: <TopologyDescription id: 603621a96ad1aa0deb7b15cb, topology_type: Single, servers: [<ServerDescription ('localhost', 27017) server_type: Unknown, rtt: None, error=AutoReconnect('localhost:27017: [Errno 111] Connection refused')>]>
[E 210224 09:52:13 web:2239] 500 GET /patient/insurance/detail (172.25.0.1) 30264.16ms
[E 210224 09:52:26 web:1789] Uncaught exception GET /patient/insurance/detail (172.25.0.1)
    HTTPServerRequest(protocol='http', host='localhost:8081', method='GET', uri='/patient/insurance/detail', version='HTTP/1.1', remote_ip='172.25.0.1')
    Traceback (most recent call last):
      File "/usr/local/lib/python3.8/site-packages/tornado/web.py", line 1704, in _execute
        result = await result
      File "/usr/src/app/handlers/endpoints.py", line 30, in get
        doc = await self.db.master.find_one()
      File "/usr/local/lib/python3.8/concurrent/futures/thread.py", line 57, in run
        result = self.fn(*self.args, **self.kwargs)
      File "/usr/local/lib/python3.8/site-packages/pymongo/collection.py", line 1319, in find_one
        for result in cursor.limit(-1):
      File "/usr/local/lib/python3.8/site-packages/pymongo/cursor.py", line 1207, in next
        if len(self.__data) or self._refresh():
      File "/usr/local/lib/python3.8/site-packages/pymongo/cursor.py", line 1100, in _refresh
        self.__session = self.__collection.database.client._ensure_session()
      File "/usr/local/lib/python3.8/site-packages/pymongo/mongo_client.py", line 1816, in _ensure_session
        return self.__start_session(True, causal_consistency=False)
      File "/usr/local/lib/python3.8/site-packages/pymongo/mongo_client.py", line 1766, in __start_session
        server_session = self._get_server_session()
      File "/usr/local/lib/python3.8/site-packages/pymongo/mongo_client.py", line 1802, in _get_server_session
        return self._topology.get_server_session()
      File "/usr/local/lib/python3.8/site-packages/pymongo/topology.py", line 485, in get_server_session
        self._select_servers_loop(
      File "/usr/local/lib/python3.8/site-packages/pymongo/topology.py", line 215, in _select_servers_loop
        raise ServerSelectionTimeoutError(
    pymongo.errors.ServerSelectionTimeoutError: localhost:27017: [Errno 111] Connection refused, Timeout: 30s, Topology Description: <TopologyDescription id: 603621a96ad1aa0deb7b15cb, topology_type: Single, servers: [<ServerDescription ('localhost', 27017) server_type: Unknown, rtt: None, error=AutoReconnect('localhost:27017: [Errno 111] Connection refused')>]>
[E 210224 09:52:26 web:2239] 500 GET /patient/insurance/detail (172.25.0.1) 30092.00ms
[E 210224 09:55:10 web:1789] Uncaught exception GET /patient/insurance/detail (172.26.0.1)
    HTTPServerRequest(protocol='http', host='localhost:8081', method='GET', uri='/patient/insurance/detail', version='HTTP/1.1', remote_ip='172.26.0.1')
    Traceback (most recent call last):
      File "/usr/local/lib/python3.8/site-packages/tornado/web.py", line 1704, in _execute
        result = await result
      File "/usr/src/app/handlers/endpoints.py", line 30, in get
        doc = await self.db.master.find_one()
      File "/usr/local/lib/python3.8/concurrent/futures/thread.py", line 57, in run
        result = self.fn(*self.args, **self.kwargs)
      File "/usr/local/lib/python3.8/site-packages/pymongo/collection.py", line 1319, in find_one
        for result in cursor.limit(-1):
      File "/usr/local/lib/python3.8/site-packages/pymongo/cursor.py", line 1207, in next
        if len(self.__data) or self._refresh():
      File "/usr/local/lib/python3.8/site-packages/pymongo/cursor.py", line 1100, in _refresh
        self.__session = self.__collection.database.client._ensure_session()
      File "/usr/local/lib/python3.8/site-packages/pymongo/mongo_client.py", line 1816, in _ensure_session
        return self.__start_session(True, causal_consistency=False)
      File "/usr/local/lib/python3.8/site-packages/pymongo/mongo_client.py", line 1766, in __start_session
        server_session = self._get_server_session()
      File "/usr/local/lib/python3.8/site-packages/pymongo/mongo_client.py", line 1802, in _get_server_session
        return self._topology.get_server_session()
      File "/usr/local/lib/python3.8/site-packages/pymongo/topology.py", line 485, in get_server_session
        self._select_servers_loop(
      File "/usr/local/lib/python3.8/site-packages/pymongo/topology.py", line 215, in _select_servers_loop
        raise ServerSelectionTimeoutError(
    pymongo.errors.ServerSelectionTimeoutError: localhost:27017: [Errno 111] Connection refused, Timeout: 30s, Topology Description: <TopologyDescription id: 603622195a3072f1a01590ac, topology_type: Single, servers: [<ServerDescription ('localhost', 27017) server_type: Unknown, rtt: None, error=AutoReconnect('localhost:27017: [Errno 111] Connection refused')>]>
[E 210224 09:55:10 web:2239] 500 GET /patient/insurance/detail (172.26.0.1) 30235.92ms
[E 210224 09:59:28 web:1789] Uncaught exception GET /patient/insurance/detail (172.26.0.1)
    HTTPServerRequest(protocol='http', host='localhost:8081', method='GET', uri='/patient/insurance/detail', version='HTTP/1.1', remote_ip='172.26.0.1')
    Traceback (most recent call last):
      File "/usr/local/lib/python3.8/site-packages/tornado/web.py", line 1704, in _execute
        result = await result
      File "/usr/src/app/handlers/endpoints.py", line 36, in get
        self.send_response(payload)
      File "/usr/src/app/handlers/core.py", line 74, in send_response
        self.finish(_response)
      File "/usr/local/lib/python3.8/site-packages/tornado/web.py", line 1127, in finish
        self.write(chunk)
      File "/usr/local/lib/python3.8/site-packages/tornado/web.py", line 843, in write
        chunk = escape.json_encode(chunk)
      File "/usr/local/lib/python3.8/site-packages/tornado/escape.py", line 75, in json_encode
        return json.dumps(value).replace("</", "<\\/")
      File "/usr/local/lib/python3.8/json/__init__.py", line 231, in dumps
        return _default_encoder.encode(obj)
      File "/usr/local/lib/python3.8/json/encoder.py", line 199, in encode
        chunks = self.iterencode(o, _one_shot=True)
      File "/usr/local/lib/python3.8/json/encoder.py", line 257, in iterencode
        return _iterencode(o, 0)
      File "/usr/local/lib/python3.8/json/encoder.py", line 179, in default
        raise TypeError(f'Object of type {o.__class__.__name__} '
    TypeError: Object of type ObjectId is not JSON serializable
[E 210224 09:59:28 web:2239] 500 GET /patient/insurance/detail (172.26.0.1) 58.31ms
[I 210224 10:00:10 autoreload:201] /usr/src/app/handlers/endpoints.py modified; restarting server
[E 210224 10:00:15 web:1789] Uncaught exception GET /patient/insurance/detail (172.26.0.1)
    HTTPServerRequest(protocol='http', host='localhost:8081', method='GET', uri='/patient/insurance/detail', version='HTTP/1.1', remote_ip='172.26.0.1')
    Traceback (most recent call last):
      File "/usr/local/lib/python3.8/site-packages/tornado/web.py", line 1704, in _execute
        result = await result
      File "/usr/src/app/handlers/endpoints.py", line 32, in get
        p = doc.policy
    AttributeError: 'dict' object has no attribute 'policy'
[E 210224 10:00:15 web:2239] 500 GET /patient/insurance/detail (172.26.0.1) 40.16ms
[I 210224 10:00:34 autoreload:201] /usr/src/app/handlers/endpoints.py modified; restarting server
[I 210224 10:00:39 autoreload:201] /usr/src/app/handlers/endpoints.py modified; restarting server
[I 210224 10:00:42 web:2239] 200 GET /patient/insurance/detail (172.26.0.1) 22.96ms
[I 210224 10:01:48 autoreload:201] /usr/src/app/handlers/endpoints.py modified; restarting server
[I 210224 10:01:50 web:2239] 200 GET /patient/insurance/detail (172.26.0.1) 30.84ms
[I 210224 11:37:52 web:2239] 200 GET /patient/insurance/detail (172.26.0.1) 35.23ms
[W 210224 11:38:40 web:2239] 404 GET / (172.26.0.1) 9.68ms
[I 210224 12:09:30 web:2239] 200 GET /patient/insurance/detail (172.26.0.1) 29.93ms
[I 210224 12:22:48 web:2239] 200 GET /patient/insurance/detail (172.27.0.1) 33.55ms
[I 210224 12:22:49 web:2239] 200 GET /patient/insurance/detail (172.27.0.1) 3.48ms
[I 210224 12:54:18 web:2239] 200 GET /patient/insurance/detail (172.30.0.1) 48.31ms
[W 210224 12:54:19 web:2239] 404 GET /favicon.ico (172.30.0.1) 7.11ms
[I 210225 04:23:53 web:2239] 200 GET /patient/insurance/detail (172.30.0.1) 41.33ms
[W 210225 04:23:54 web:2239] 404 GET /favicon.ico (172.30.0.1) 6.42ms
[I 210225 05:02:38 web:2239] 200 GET /patient/insurance/detail (172.30.0.1) 2.77ms
[I 210225 05:02:53 web:2239] 200 GET /patient/insurance/detail (172.30.0.1) 5.70ms
[I 210225 05:06:29 web:2239] 200 GET /patient/insurance/detail (172.30.0.1) 5.97ms
[I 210225 05:11:30 web:2239] 200 GET /patient/insurance/detail (172.30.0.1) 3.82ms
[I 210225 05:11:56 web:2239] 200 GET /patient/insurance/detail (172.30.0.1) 14.13ms
[I 210225 05:12:57 web:2239] 200 GET /patient/insurance/detail (172.30.0.1) 8.03ms
[I 210225 05:13:12 web:2239] 200 GET /patient/insurance/detail (172.30.0.1) 7.70ms
[I 210225 08:48:56 web:2239] 200 GET /patient/insurance/detail (172.30.0.1) 6.24ms
[I 210225 08:49:40 web:2239] 200 GET /patient/insurance/detail (172.30.0.1) 7.17ms
[I 210225 08:50:35 web:2239] 200 GET /patient/insurance/detail (172.30.0.1) 7.78ms
[I 210225 08:51:04 web:2239] 200 GET /patient/insurance/detail (172.30.0.1) 6.23ms
[I 210225 08:51:18 web:2239] 200 GET /patient/insurance/detail (172.30.0.1) 8.70ms
[I 210225 08:53:59 web:2239] 200 GET /patient/insurance/detail (172.30.0.1) 5.40ms
[W 210225 08:54:36 web:2239] 404 GET /patient/insurance/detal (172.30.0.1) 3.00ms
[W 210225 09:02:03 web:2239] 404 GET /patient/insurance/detal (172.30.0.1) 3.36ms
[W 210225 09:02:03 web:2239] 404 GET /favicon.ico (172.30.0.1) 1.95ms
[I 210225 09:02:10 web:2239] 200 GET /patient/insurance/detail (172.30.0.1) 8.18ms
[I 210225 09:20:00 web:2239] 200 GET /patient/insurance/detail (172.30.0.1) 4.84ms
[I 210225 09:20:39 web:2239] 200 GET /patient/insurance/detail (172.30.0.1) 7.80ms
[I 210225 09:20:54 web:2239] 200 GET /patient/insurance/detail (172.30.0.1) 5.58ms
[I 210225 09:21:40 web:2239] 200 GET /patient/insurance/detail (172.30.0.1) 6.87ms
[I 210225 09:26:11 web:2239] 200 GET /patient/insurance/detail (172.30.0.1) 5.31ms
[I 210225 09:26:47 web:2239] 200 GET /patient/insurance/detail (172.30.0.1) 9.98ms
[I 210225 09:27:47 web:2239] 200 GET /patient/insurance/detail (172.30.0.1) 6.65ms
[I 210225 09:28:25 web:2239] 200 GET /patient/insurance/detail (172.30.0.1) 8.50ms
[I 210225 09:29:06 web:2239] 200 GET /patient/insurance/detail (172.30.0.1) 4.96ms
[I 210225 09:29:42 web:2239] 200 GET /patient/insurance/detail (172.30.0.1) 7.36ms
[I 210225 09:30:10 web:2239] 200 GET /patient/insurance/detail (172.30.0.1) 11.29ms
[I 210225 09:30:31 web:2239] 200 GET /patient/insurance/detail (172.30.0.1) 6.99ms
[I 210225 10:18:45 web:2239] 200 GET /patient/insurance/detail (172.30.0.1) 12.66ms
[I 210225 10:19:13 web:2239] 200 GET /patient/insurance/detail (172.30.0.1) 5.54ms
[I 210225 10:19:17 web:2239] 200 GET /patient/insurance/detail (172.30.0.1) 7.98ms
[I 210225 10:20:05 web:2239] 200 GET /patient/insurance/detail (172.30.0.1) 4.48ms
[I 210225 10:20:53 web:2239] 200 GET /patient/insurance/detail (172.30.0.1) 9.58ms
[I 210225 10:21:20 web:2239] 200 GET /patient/insurance/detail (172.30.0.1) 7.71ms
[I 210225 10:21:35 web:2239] 200 GET /patient/insurance/detail (172.30.0.1) 4.57ms
[I 210225 10:22:18 web:2239] 200 GET /patient/insurance/detail (172.30.0.1) 5.40ms
[I 210225 10:23:56 web:2239] 200 GET /patient/insurance/detail (172.30.0.1) 3.82ms
[I 210225 10:24:29 web:2239] 200 GET /patient/insurance/detail (172.30.0.1) 8.64ms
[I 210225 10:25:01 web:2239] 200 GET /patient/insurance/detail (172.30.0.1) 6.86ms
[I 210225 10:25:52 web:2239] 200 GET /patient/insurance/detail (172.30.0.1) 10.39ms
[I 210225 10:28:47 web:2239] 200 GET /patient/insurance/detail (172.30.0.1) 5.53ms
[I 210225 10:29:52 web:2239] 200 GET /patient/insurance/detail (172.30.0.1) 4.21ms
[I 210225 10:29:55 web:2239] 200 GET /patient/insurance/detail (172.30.0.1) 8.56ms
[I 210225 10:30:24 web:2239] 200 GET /patient/insurance/detail (172.30.0.1) 7.89ms
[I 210225 10:30:50 web:2239] 200 GET /patient/insurance/detail (172.30.0.1) 11.00ms
[I 210225 10:33:33 web:2239] 200 GET /patient/insurance/detail (172.30.0.1) 11.05ms
[I 210225 10:33:43 web:2239] 200 GET /patient/insurance/detail (172.30.0.1) 4.72ms
[I 210225 10:34:25 web:2239] 200 GET /patient/insurance/detail (172.30.0.1) 33.87ms
[W 210225 15:28:08 web:2239] 404 GET /run/compare?base=6037861785884f1a008b4576 (172.30.0.1) 1.94ms
[I 210226 05:15:34 web:2239] 200 GET /patient/insurance/detail (172.30.0.1) 29.40ms
[I 210226 05:15:59 web:2239] 200 GET /patient/insurance/detail (172.30.0.1) 6.64ms
[I 210226 05:22:03 web:2239] 200 GET /patient/insurance/detail (172.30.0.1) 9.19ms
[I 210226 06:14:41 web:2239] 200 GET /patient/insurance/detail (172.30.0.1) 6.09ms
[I 210226 06:17:55 web:2239] 200 GET /patient/insurance/detail (172.30.0.1) 4.38ms
[I 210226 06:18:24 web:2239] 200 GET /patient/insurance/detail (172.30.0.1) 3.54ms
[I 210226 06:19:03 web:2239] 200 GET /patient/insurance/detail (172.30.0.1) 6.92ms
[I 210226 06:21:46 web:2239] 200 GET /patient/insurance/detail (172.30.0.1) 5.62ms
[I 210226 06:25:16 web:2239] 200 GET /patient/insurance/detail (172.30.0.1) 4.76ms
[I 210226 06:28:30 web:2239] 200 GET /patient/insurance/detail (172.30.0.1) 2.91ms
[I 210226 06:30:46 web:2239] 200 GET /patient/insurance/detail (172.30.0.1) 4.55ms
[I 210226 06:31:00 web:2239] 200 GET /patient/insurance/detail (172.30.0.1) 6.81ms
[I 210226 06:34:20 web:2239] 200 GET /patient/insurance/detail (172.30.0.1) 6.85ms
[I 210226 06:34:43 web:2239] 200 GET /patient/insurance/detail (172.30.0.1) 9.83ms
[I 210226 06:40:42 web:2239] 200 GET /patient/insurance/detail (172.30.0.1) 3.66ms
[I 210226 07:28:03 web:2239] 200 GET /patient/insurance/detail (172.30.0.1) 18.32ms
[I 210226 07:28:35 web:2239] 200 GET /patient/insurance/detail (172.30.0.1) 10.48ms
[I 210226 07:28:50 web:2239] 200 GET /patient/insurance/detail (172.30.0.1) 13.60ms
[I 210226 07:29:51 web:2239] 200 GET /patient/insurance/detail (172.30.0.1) 5.49ms
[I 210226 07:30:36 web:2239] 200 GET /patient/insurance/detail (172.30.0.1) 4.72ms
[I 210226 07:33:47 web:2239] 200 GET /patient/insurance/detail (172.30.0.1) 4.99ms
[I 210226 07:33:55 web:2239] 200 GET /patient/insurance/detail (172.30.0.1) 11.38ms
[I 210226 07:34:20 web:2239] 200 GET /patient/insurance/detail (172.30.0.1) 9.14ms
[I 210226 07:37:11 web:2239] 200 GET /patient/insurance/detail (172.30.0.1) 4.91ms
[I 210226 07:39:41 web:2239] 200 GET /patient/insurance/detail (172.30.0.1) 11.38ms
[I 210226 09:33:05 web:2239] 200 GET /patient/insurance/detail (172.30.0.1) 100.23ms
[W 210226 09:33:06 web:2239] 404 GET /favicon.ico (172.30.0.1) 8.99ms
[I 210226 11:08:06 web:2239] 200 GET /patient/insurance/detail (172.30.0.1) 4.11ms
[I 210226 11:11:04 web:2239] 200 GET /patient/insurance/detail (172.30.0.1) 7.80ms
[I 210226 11:13:49 autoreload:201] /usr/src/app/handlers/endpoints.py modified; restarting server
[I 210226 11:27:22 autoreload:201] /usr/src/app/handlers/endpoints.py modified; restarting server
[I 210226 11:29:27 web:2239] 200 GET /patient/insurance/detail (172.30.0.1) 35.90ms
[I 210226 11:50:15 web:2239] 200 GET /patient/insurance/detail (172.30.0.10) 6.62ms
[I 210226 11:50:44 web:2239] 200 GET /patient/insurance/detail (172.30.0.10) 4.94ms
[I 210226 11:51:02 web:2239] 200 GET /patient/insurance/detail (172.30.0.10) 7.92ms
[I 210226 11:51:07 web:2239] 200 GET /patient/insurance/detail (172.30.0.10) 9.24ms
[I 210226 11:51:23 web:2239] 200 GET /patient/insurance/detail (172.30.0.10) 11.61ms
[I 210226 11:52:38 web:2239] 200 GET /patient/insurance/detail (172.30.0.10) 15.34ms
[I 210226 11:54:33 web:2239] 200 GET /patient/insurance/detail (172.30.0.10) 4.08ms
[I 210226 12:03:21 web:2239] 200 GET /patient/insurance/detail (172.30.0.1) 11.92ms
[I 210226 12:04:03 web:2239] 200 GET /patient/insurance/detail (172.30.0.10) 3.08ms
[I 210226 12:04:52 web:2239] 200 GET /patient/insurance/detail (172.30.0.10) 5.57ms
